<?xml version="1.0"?>
<robot name="four_dof_arm">
    <material name="blue">
        <color rgba="0.1 0.1 0.8 1.0"/>
    </material>
    <material name="red">
        <color rgba="0.8 0.1 0.1 1.0"/>
    </material>
    <material name="grey">
        <color rgba="0.7 0.7 0.7 1.0"/>
    </material>
    
    <link name="base_link">
        <visual>
            <origin xyz="0 0 0.05" rpy="0 0 0"/>
            <geometry>
                <box size="0.2 0.2 0.1"/>
            </geometry>
            <material name="grey"/>
        </visual>
        <collision>
            <origin xyz="0 0 0.05" rpy="0 0 0"/>
            <geometry>
                <box size="0.2 0.2 0.1"/>
            </geometry>
        </collision>
        <inertial>
            <origin xyz="0 0 0" rpy="0 0 0"/>
            <mass value="1.0"/>
            <inertia ixx="0.01" ixy="0" ixz="0" iyy="0.01" iyz="0" izz="0.01"/>
        </inertial>
    </link>

    <joint name="joint1_base_yaw" type="revolute">
        <origin xyz="0 0 0.1" rpy="0 0 0"/>
        <parent link="base_link"/>
        <child link="link1_shoulder"/>
        <axis xyz="0 0 1"/>
        <limit effort="100.0" velocity="0.5" lower="-3.14" upper="3.14"/>
    </joint>

    <link name="link1_shoulder">
        <visual>
            <origin xyz="0 0 0.05" rpy="0 0 0"/>
            <geometry>
                <cylinder radius="0.04" length="0.1"/>
            </geometry>
            <material name="blue"/>
        </visual>
        <collision>
            <origin xyz="0 0 0.05" rpy="0 0 0"/>
            <geometry>
                <cylinder radius="0.04" length="0.1"/>
            </geometry>
        </collision>
        <inertial>
            <origin xyz="0 0 0" rpy="0 0 0"/>
            <mass value="0.5"/>
            <inertia ixx="0.005" ixy="0" ixz="0" iyy="0.005" iyz="0" izz="0.005"/>
        </inertial>
    </link>

    <joint name="joint2_shoulder_pitch" type="revolute">
        <origin xyz="0 0 0.1" rpy="0 0 0"/>
        <parent link="link1_shoulder"/>
        <child link="link2_upper_arm"/>
        <axis xyz="0 1 0"/>
        <limit effort="100.0" velocity="0.5" lower="-1.57" upper="1.57"/>
    </joint>

    <link name="link2_upper_arm">
        <visual>
            <origin xyz="0.25 0 0" rpy="0 1.5708 0"/> 
            <geometry>
                <cylinder radius="0.03" length="0.5"/>
            </geometry>
            <material name="red"/>
        </visual>
        <collision>
            <origin xyz="0.25 0 0" rpy="0 1.5708 0"/>
            <geometry>
                <cylinder radius="0.03" length="0.5"/>
            </geometry>
        </collision>
        <inertial>
            <origin xyz="0 0 0" rpy="0 1.5708 0"/> <mass value="0.75"/>
            <inertia ixx="0.0075" ixy="0" ixz="0" iyy="0.0075" iyz="0" izz="0.0075"/>
        </inertial>
    </link>

    <joint name="joint3_elbow_pitch" type="revolute">
        <origin xyz="0.5 0 0" rpy="0 0 0"/>
        <parent link="link2_upper_arm"/>
        <child link="link3_forearm"/>
        <axis xyz="0 1 0"/> 
        <limit effort="100.0" velocity="0.5" lower="-2.0" upper="2.0"/> 
    </joint>

    <link name="link3_forearm">
        <visual>
            <origin xyz="0.25 0 0" rpy="0 1.5708 0"/>
            <geometry>
                <cylinder radius="0.03" length="0.5"/>
            </geometry>
            <material name="blue"/>
        </visual>
        <collision>
            <origin xyz="0.25 0 0" rpy="0 1.5708 0"/>
            <geometry>
                <cylinder radius="0.03" length="0.5"/>
            </geometry>
        </collision>
        <inertial>
            <origin xyz="0.25 0 0" rpy="0 1.5708 0"/>
            <mass value="0.5"/>
            <inertia ixx="0.005" ixy="0" ixz="0" iyy="0.005" iyz="0" izz="0.005"/>
        </inertial>
    </link>

    <joint name="joint4_wrist_roll" type="revolute">
        <origin xyz="0.5 0 0" rpy="0 0 0"/>
        <parent link="link3_forearm"/>
        <child link="tool_link"/>
        <axis xyz="1 0 0"/> 
        <limit effort="50.0" velocity="1.0" lower="-3.14" upper="3.14"/> 
    </joint>

   
    <link name="tool_link">
        <visual>
            <origin xyz="0.05 0 0" rpy="0 0 0"/>
            <geometry>
                <box size="0.1 0.06 0.02"/>
            </geometry>
            <material name="red"/>
        </visual>
        <collision>
            <origin xyz="0.05 0 0" rpy="0 0 0"/>
            <geometry>
                <box size="0.1 0.06 0.02"/>
            </geometry>
        </collision>
        <inertial>
            <origin xyz="0.05 0 0" rpy="0 0 0"/>
            <mass value="0.1"/>
            <inertia ixx="0.001" ixy="0" ixz="0" iyy="0.001" iyz="0" izz="0.001"/>
        </inertial>
    </link>

</robot>