<?xml version="1.0"?>
<robot name="four_dof_arm_with_gripper">
    <!-- Material Definitions -->
    <material name="blue">
        <color rgba="0.1 0.1 0.8 1.0"/>
    </material>
    <material name="red">
        <color rgba="0.8 0.1 0.1 1.0"/>
    </material>
    <material name="grey">
        <color rgba="0.7 0.7 0.7 1.0"/>
    </material>
    
    <!-- BASE LINK (No Change) -->
    <link name="base_link">
        <visual>
            <origin xyz="0 0 0.05" rpy="0 0 0"/>
            <geometry><box size="0.2 0.2 0.1"/></geometry>
            <material name="grey"/>
        </visual>
        <collision>
            <origin xyz="0 0 0.05" rpy="0 0 0"/>
            <geometry><box size="0.2 0.2 0.1"/></geometry>
        </collision>
        <inertial>
            <origin xyz="0 0 0" rpy="0 0 0"/>
            <mass value="1.0"/>
            <inertia ixx="0.01" ixy="0" ixz="0" iyy="0.01" iyz="0" izz="0.01"/>
        </inertial>
    </link>

    <!-- JOINT 1 (No Change) -->
    <joint name="joint1_base_yaw" type="revolute">
        <origin xyz="0 0 0.1" rpy="0 0 0"/>
        <parent link="base_link"/>
        <child link="link1_shoulder"/>
        <axis xyz="0 0 1"/>
        <limit effort="100.0" velocity="0.5" lower="-3.14" upper="3.14"/>
    </joint>

    <!-- LINK 1 (No Change) -->
    <link name="link1_shoulder">
        <visual>
            <origin xyz="0 0 0.05" rpy="0 0 0"/>
            <geometry><cylinder radius="0.04" length="0.1"/></geometry>
            <material name="blue"/>
        </visual>
        <collision>
            <origin xyz="0 0 0.05" rpy="0 0 0"/>
            <geometry><cylinder radius="0.04" length="0.1"/></geometry>
        </collision>
        <inertial>
            <origin xyz="0 0 0" rpy="0 0 0"/>
            <mass value="0.5"/>
            <inertia ixx="0.005" ixy="0" ixz="0" iyy="0.005" iyz="0" izz="0.005"/>
        </inertial>
    </link>

    <!-- JOINT 2 (No Change) -->
    <joint name="joint2_shoulder_pitch" type="revolute">
        <origin xyz="0 0 0.1" rpy="0 0 0"/>
        <parent link="link1_shoulder"/>
        <child link="link2_upper_arm"/>
        <axis xyz="0 1 0"/>
        <limit effort="100.0" velocity="0.5" lower="-1.57" upper="1.57"/>
    </joint>

    <!-- LINK 2 (No Change) -->
    <link name="link2_upper_arm">
        <visual>
            <origin xyz="0.25 0 0" rpy="0 1.5708 0"/> 
            <geometry><cylinder radius="0.03" length="0.5"/></geometry>
            <material name="red"/>
        </visual>
        <collision>
            <origin xyz="0.25 0 0" rpy="0 1.5708 0"/>
            <geometry><cylinder radius="0.03" length="0.5"/></geometry>
        </collision>
        <inertial>
            <origin xyz="0 0 0" rpy="0 1.5708 0"/> 
            <mass value="0.75"/>
            <inertia ixx="0.0075" ixy="0" ixz="0" iyy="0.0075" iyz="0" izz="0.0075"/>
        </inertial>
    </link>

    <!-- JOINT 3 (No Change) -->
    <joint name="joint3_elbow_pitch" type="revolute">
        <origin xyz="0.5 0 0" rpy="0 0 0"/>
        <parent link="link2_upper_arm"/>
        <child link="link3_forearm"/>
        <axis xyz="0 1 0"/> 
        <limit effort="100.0" velocity="0.5" lower="-2.0" upper="2.0"/> 
    </joint>

    <!-- LINK 3 (No Change) -->
    <link name="link3_forearm">
        <visual>
            <origin xyz="0.25 0 0" rpy="0 1.5708 0"/>
            <geometry><cylinder radius="0.03" length="0.5"/></geometry>
            <material name="blue"/>
        </visual>
        <collision>
            <origin xyz="0.25 0 0" rpy="0 1.5708 0"/>
            <geometry><cylinder radius="0.03" length="0.5"/></geometry>
        </collision>
        <inertial>
            <origin xyz="0.25 0 0" rpy="0 1.5708 0"/>
            <mass value="0.5"/>
            <inertia ixx="0.005" ixy="0" ixz="0" iyy="0.005" iyz="0" izz="0.005"/>
        </inertial>
    </link>
    <!-- JOINT 4: WRIST PITCH -->
    <joint name="joint4_wrist_pitch" type="revolute">
        <origin xyz="0.5 0 0" rpy="0 0 0"/>
        <parent link="link3_forearm"/>
        <child link="gripper_base"/>
        <axis xyz="0 1 0"/>
        <limit effort="50.0" velocity="1.0" lower="-3.14" upper="3.14"/>
    </joint>

    <!-- GRIPPER BASE (BOTTOM PLATE) -->
    <link name="gripper_base">
        <visual>
            <origin xyz="0 0 0" rpy="0 0 0"/>
            <geometry>
                <mesh filename="meshes/gripper_plate_bottom.stl" scale="0.001 0.001 0.001"/>
            </geometry>
        </visual>
        <collision>
            <origin xyz="0 0 0" rpy="0 0 0"/>
            <geometry>
                <mesh filename="meshes/gripper_plate_bottom.stl" scale="0.001 0.001 0.001"/>
            </geometry>
        </collision>
        <inertial>
            <mass value="0.05"/>
            <inertia ixx="0.0001" ixy="0" ixz="0" iyy="0.0001" iyz="0" izz="0.0001"/>
        </inertial>
    </link>

    <!-- TOP PLATE (FIXED TO BASE) -->
    <link name="gripper_top_plate">
        <visual>
            <origin xyz="0 0 0.01" rpy="0 0 0"/>
            <geometry>
                <mesh filename="meshes/gripper_plate_top.stl" scale="0.001 0.001 0.001"/>
            </geometry>
        </visual>
    </link>

    <joint name="gripper_fixed_top" type="fixed">
        <origin xyz="0 0 0" rpy="0 0 0"/>
        <parent link="gripper_base"/>
        <child link="gripper_top_plate"/>
    </joint>

    <!-- LEFT FINGER -->
    <joint name="gripper_joint_left" type="prismatic">
        <origin xyz="0 0.02 0" rpy="0 0 0"/>
        <parent link="gripper_base"/>
        <child link="gripper_left"/>
        <axis xyz="0 1 0"/>
        <limit effort="20.0" velocity="0.3" lower="0.0" upper="0.03"/>
    </joint>

    <link name="gripper_left">
        <visual>
            <origin xyz="0 0.02 0" rpy="0 0 0"/>
            <geometry>
                <mesh filename="meshes/gripper_left.stl" scale="0.001 0.001 0.001"/>
            </geometry>
        </visual>
        <collision>
            <origin xyz="0 0.02 0" rpy="0 0 0"/>
            <geometry>
                <mesh filename="meshes/gripper_left.stl" scale="0.001 0.001 0.001"/>
            </geometry>
        </collision>
    </link>

    <!-- RIGHT FINGER -->
    <joint name="gripper_joint_right" type="prismatic">
        <origin xyz="0 -0.02 0" rpy="0 0 0"/>
        <parent link="gripper_base"/>
        <child link="gripper_right"/>
        <axis xyz="0 -1 0"/>
        <limit effort="20.0" velocity="0.3" lower="0.0" upper="0.03"/>
    </joint>

    <link name="gripper_right">
        <visual>
            <origin xyz="0 -0.02 0" rpy="0 0 0"/>
            <geometry>
                <mesh filename="meshes/gripper_right.stl" scale="0.001 0.001 0.001"/>
            </geometry>
        </visual>
        <collision>
            <origin xyz="0 -0.02 0" rpy="0 0 0"/>
            <geometry>
                <mesh filename="meshes/gripper_right.stl" scale="0.001 0.001 0.001"/>
            </geometry>
        </collision>
    </link>



</robot>
